Workbook

Sheet INFO AÇÕES
A1: Ações | B1: Abreviatura do câmbio | C1: Preço | D1: Bolsa | E1: Símbolo do ticker | F1: Hora da última transação | G1: Variação | H1: Variação (%) | I1: Moeda | J1: Conversão MOEDA | K1: Preço Dolar | L1: Da moeda | M1: Moeda2
A2: #VALUE! | B2: {=_FV(A2,"Abreviatura do câmbio",TRUE)} -> BVMF | C2: {=_FV(A2,"Preço")} -> 17.81 | D2: {=_FV(A2,"Bolsa")} -> B3 - Brazil Stock Exchange | E2: {=_FV(A2,"Símbolo do ticker",TRUE)} -> BBAS3 | F2: {=_FV(A2,"Hora da última transação",TRUE)} -> 46322.66 | G2: {=_FV(A2,"Variação")} -> 0.34 | H2: {=_FV(A2,"Variação (%)",TRUE)} -> 0.019462 | I2: {=_FV(tb_acoes[[#This Row],[Ações]],"Moeda")} -> BRL | K2: {=IFERROR(_FV(J2,"Preço"),"")} | L2: {=IFERROR(_FV(J2,"Da moeda",TRUE),"")} | M2: {=IFERROR(_FV(J2,"Moeda"),"")}
A3: #VALUE! | B3: {=_FV(A3,"Abreviatura do câmbio",TRUE)} -> BVMF | C3: {=_FV(A3,"Preço")} -> 35.67 | D3: {=_FV(A3,"Bolsa")} -> B3 - Brazil Stock Exchange | E3: {=_FV(A3,"Símbolo do ticker",TRUE)} -> EQTL3 | F3: {=_FV(A3,"Hora da última transação",TRUE)} -> 46322.66 | G3: {=_FV(A3,"Variação")} -> 0.83 | H3: {=_FV(A3,"Variação (%)",TRUE)} -> 0.023823 | I3: {=_FV(tb_acoes[[#This Row],[Ações]],"Moeda")} -> BRL | K3: {=IFERROR(_FV(J3,"Preço"),"")} | L3: {=IFERROR(_FV(J3,"Da moeda",TRUE),"")} | M3: {=IFERROR(_FV(J3,"Moeda"),"")}
A4: #VALUE! | B4: {=_FV(A4,"Abreviatura do câmbio",TRUE)} -> BVMF | C4: {=_FV(A4,"Preço")} -> 25.43 | D4: {=_FV(A4,"Bolsa")} -> B3 - Brazil Stock Exchange | E4: {=_FV(A4,"Símbolo do ticker",TRUE)} -> SBSP3 | F4: {=_FV(A4,"Hora da última transação",TRUE)} -> 46322.66 | G4: {=_FV(A4,"Variação")} -> 0.16 | H4: {=_FV(A4,"Variação (%)",TRUE)} -> 0.006332 | I4: {=_FV(tb_acoes[[#This Row],[Ações]],"Moeda")} -> BRL | K4: {=IFERROR(_FV(J4,"Preço"),"")} | L4: {=IFERROR(_FV(J4,"Da moeda",TRUE),"")} | M4: {=IFERROR(_FV(J4,"Moeda"),"")}
A5: #VALUE! | B5: {=_FV(A5,"Abreviatura do câmbio",TRUE)} -> BVMF | C5: {=_FV(A5,"Preço")} -> 6.86 | D5: {=_FV(A5,"Bolsa")} -> B3 - Brazil Stock Exchange | E5: {=_FV(A5,"Símbolo do ticker",TRUE)} -> SAPR4 | F5: {=_FV(A5,"Hora da última transação",TRUE)} -> 46322.66 | G5: {=_FV(A5,"Variação")} -> 0.06 | H5: {=_FV(A5,"Variação (%)",TRUE)} -> 0.008824 | I5: {=_FV(tb_acoes[[#This Row],[Ações]],"Moeda")} -> BRL | K5: {=IFERROR(_FV(J5,"Preço"),"")} | L5: {=IFERROR(_FV(J5,"Da moeda",TRUE),"")} | M5: {=IFERROR(_FV(J5,"Moeda"),"")}
A6: #VALUE! | B6: {=_FV(A6,"Abreviatura do câmbio",TRUE)} -> BVMF | C6: {=_FV(A6,"Preço")} -> 13.97 | D6: {=_FV(A6,"Bolsa")} -> B3 - Brazil Stock Exchange | E6: {=_FV(A6,"Símbolo do ticker",TRUE)} -> ITSA3 | F6: {=_FV(A6,"Hora da última transação",TRUE)} -> 46322.66 | G6: {=_FV(A6,"Variação")} -> -0.13 | H6: {=_FV(A6,"Variação (%)",TRUE)} -> -0.00922 | I6: {=_FV(tb_acoes[[#This Row],[Ações]],"Moeda")} -> BRL | K6: {=IFERROR(_FV(J6,"Preço"),"")} | L6: {=IFERROR(_FV(J6,"Da moeda",TRUE),"")} | M6: {=IFERROR(_FV(J6,"Moeda"),"")}
A7: #VALUE! | B7: {=_FV(A7,"Abreviatura do câmbio",TRUE)} -> BVMF | C7: {=_FV(A7,"Preço")} -> 91.8 | D7: {=_FV(A7,"Bolsa")} -> B3 - Brazil Stock Exchange | E7: {=_FV(A7,"Símbolo do ticker",TRUE)} -> XPLG11 | F7: {=_FV(A7,"Hora da última transação",TRUE)} -> 46322.66 | G7: {=_FV(A7,"Variação")} -> -1.32 | H7: {=_FV(A7,"Variação (%)",TRUE)} -> -0.014175 | I7: {=_FV(tb_acoes[[#This Row],[Ações]],"Moeda")} -> BRL | K7: {=IFERROR(_FV(J7,"Preço"),"")} | L7: {=IFERROR(_FV(J7,"Da moeda",TRUE),"")} | M7: {=IFERROR(_FV(J7,"Moeda"),"")}
A8: #VALUE! | B8: {=_FV(A8,"Abreviatura do câmbio",TRUE)} -> BVMF | C8: {=_FV(A8,"Preço")} -> 149 | D8: {=_FV(A8,"Bolsa")} -> B3 - Brazil Stock Exchange | E8: {=_FV(A8,"Símbolo do ticker",TRUE)} -> HGLG11 | F8: {=_FV(A8,"Hora da última transação",TRUE)} -> 46322.66 | G8: {=_FV(A8,"Variação")} -> -2.7 | H8: {=_FV(A8,"Variação (%)",TRUE)} -> -0.017798 | I8: {=_FV(tb_acoes[[#This Row],[Ações]],"Moeda")} -> BRL | K8: {=IFERROR(_FV(J8,"Preço"),"")} | L8: {=IFERROR(_FV(J8,"Da moeda",TRUE),"")} | M8: {=IFERROR(_FV(J8,"Moeda"),"")}
A9: #VALUE! | B9: {=_FV(A9,"Abreviatura do câmbio",TRUE)} -> BVMF | C9: {=_FV(A9,"Preço")} -> 151.45 | D9: {=_FV(A9,"Bolsa")} -> B3 - Brazil Stock Exchange | E9: {=_FV(A9,"Símbolo do ticker",TRUE)} -> KNRI11 | F9: {=_FV(A9,"Hora da última transação",TRUE)} -> 46322.66 | G9: {=_FV(A9,"Variação")} -> -2 | H9: {=_FV(A9,"Variação (%)",TRUE)} -> -0.013034 | I9: {=_FV(tb_acoes[[#This Row],[Ações]],"Moeda")} -> BRL | K9: {=IFERROR(_FV(J9,"Preço"),"")} | L9: {=IFERROR(_FV(J9,"Da moeda",TRUE),"")} | M9: {=IFERROR(_FV(J9,"Moeda"),"")}
A10: #VALUE! | B10: {=_FV(A10,"Abreviatura do câmbio",TRUE)} -> BVMF | C10: {=_FV(A10,"Preço")} -> 98.61 | D10: {=_FV(A10,"Bolsa")} -> B3 - Brazil Stock Exchange | E10: {=_FV(A10,"Símbolo do ticker",TRUE)} -> BTLG11 | F10: {=_FV(A10,"Hora da última transação",TRUE)} -> 46322.66 | G10: {=_FV(A10,"Variação")} -> -1.54 | H10: {=_FV(A10,"Variação (%)",TRUE)} -> -0.015377 | I10: {=_FV(tb_acoes[[#This Row],[Ações]],"Moeda")} -> BRL | K10: {=IFERROR(_FV(J10,"Preço"),"")} | L10: {=IFERROR(_FV(J10,"Da moeda",TRUE),"")} | M10: {=IFERROR(_FV(J10,"Moeda"),"")}
A11: #VALUE! | B11: {=_FV(A11,"Abreviatura do câmbio",TRUE)} -> BVMF | C11: {=_FV(A11,"Preço")} -> 99.33 | D11: {=_FV(A11,"Bolsa")} -> B3 - Brazil Stock Exchange | E11: {=_FV(A11,"Símbolo do ticker",TRUE)} -> XPML11 | F11: {=_FV(A11,"Hora da última transação",TRUE)} -> 46322.66 | G11: {=_FV(A11,"Variação")} -> -0.87 | H11: {=_FV(A11,"Variação (%)",TRUE)} -> -0.008683 | I11: {=_FV(tb_acoes[[#This Row],[Ações]],"Moeda")} -> BRL | K11: {=IFERROR(_FV(J11,"Preço"),"")} | L11: {=IFERROR(_FV(J11,"Da moeda",TRUE),"")} | M11: {=IFERROR(_FV(J11,"Moeda"),"")}
A12: #VALUE! | B12: {=_FV(A12,"Abreviatura do câmbio",TRUE)} -> BVMF | C12: {=_FV(A12,"Preço")} -> 86.67 | D12: {=_FV(A12,"Bolsa")} -> B3 - Brazil Stock Exchange | E12: {=_FV(A12,"Símbolo do ticker",TRUE)} -> KNCA11 | F12: {=_FV(A12,"Hora da última transação",TRUE)} -> 46322.66 | G12: {=_FV(A12,"Variação")} -> -1.33 | H12: {=_FV(A12,"Variação (%)",TRUE)} -> -0.015114 | I12: {=_FV(tb_acoes[[#This Row],[Ações]],"Moeda")} -> BRL | K12: {=IFERROR(_FV(J12,"Preço"),"")} | L12: {=IFERROR(_FV(J12,"Da moeda",TRUE),"")} | M12: {=IFERROR(_FV(J12,"Moeda"),"")}
A13: #VALUE! | B13: {=_FV(A13,"Abreviatura do câmbio",TRUE)} -> BVMF | C13: {=_FV(A13,"Preço")} -> 9.02 | D13: {=_FV(A13,"Bolsa")} -> B3 - Brazil Stock Exchange | E13: {=_FV(A13,"Símbolo do ticker",TRUE)} -> MXRF11 | F13: {=_FV(A13,"Hora da última transação",TRUE)} -> 46322.66 | G13: {=_FV(A13,"Variação")} -> -0.09 | H13: {=_FV(A13,"Variação (%)",TRUE)} -> -0.009879 | I13: {=_FV(tb_acoes[[#This Row],[Ações]],"Moeda")} -> BRL | K13: {=IFERROR(_FV(J13,"Preço"),"")} | L13: {=IFERROR(_FV(J13,"Da moeda",TRUE),"")} | M13: {=IFERROR(_FV(J13,"Moeda"),"")}
... A16: #VALUE! | B16: {=_FV(A16,"Abreviatura do câmbio",TRUE)} -> BVMF | C16: {=_FV(A16,"Preço")} -> 105.28 | D16: {=_FV(A16,"Bolsa")} -> B3 - Brazil Stock Exchange | E16: {=_FV(A16,"Símbolo do ticker",TRUE)} -> KNCR11 | F16: {=_FV(A16,"Hora da última transação",TRUE)} -> 46322.66 | G16: {=_FV(A16,"Variação")} -> 0.98 | H16: {=_FV(A16,"Variação (%)",TRUE)} -> 0.009396 | I16: {=_FV(tb_acoes[[#This Row],[Ações]],"Moeda")} -> BRL | K16: {=IFERROR(_FV(J16,"Preço"),"")} | L16: {=IFERROR(_FV(J16,"Da moeda",TRUE),"")} | M16: {=IFERROR(_FV(J16,"Moeda"),"")}
A17: #VALUE! | B17: {=_FV(A17,"Abreviatura do câmbio",TRUE)} -> ARCX | C17: {=_FV(A17,"Preço")} -> 50.6625 | D17: {=_FV(A17,"Bolsa")} -> NYSE Arca | E17: {=_FV(A17,"Símbolo do ticker",TRUE)} -> TFLO | F17: {=_FV(A17,"Hora da última transação",TRUE)} -> 46322.671 | G17: {=_FV(A17,"Variação")} -> 0.0025 | H17: {=_FV(A17,"Variação (%)",TRUE)} -> 4.935e-05 | I17: {=_FV(tb_acoes[[#This Row],[Ações]],"Moeda")} -> USD | J17: #VALUE! | K17: {=IFERROR(_FV(J17,"Preço"),"")} -> 5.3414 | L17: {=IFERROR(_FV(J17,"Da moeda",TRUE),"")} -> USD | M17: {=IFERROR(_FV(J17,"Moeda"),"")} -> BRL
A18: #VALUE! | B18: {=_FV(A18,"Abreviatura do câmbio",TRUE)} -> BVMF | C18: {=_FV(A18,"Preço")} -> 8.35 | D18: {=_FV(A18,"Bolsa")} -> B3 - Brazil Stock Exchange | E18: {=_FV(A18,"Símbolo do ticker",TRUE)} -> GARE11 | F18: {=_FV(A18,"Hora da última transação",TRUE)} -> 46321.875 | G18: {=_FV(A18,"Variação")} -> -0.39 | H18: {=_FV(A18,"Variação (%)",TRUE)} -> -0.044622 | I18: {=_FV(tb_acoes[[#This Row],[Ações]],"Moeda")} -> BRL | K18: {=IFERROR(_FV(J18,"Preço"),"")} | L18: {=IFERROR(_FV(J18,"Da moeda",TRUE),"")} | M18: {=IFERROR(_FV(J18,"Moeda"),"")}
A19: #VALUE! | B19: {=_FV(A19,"Abreviatura do câmbio",TRUE)} -> ARCX | C19: {=_FV(A19,"Preço")} -> 774.07 | D19: {=_FV(A19,"Bolsa")} -> NYSE Arca | E19: {=_FV(A19,"Símbolo do ticker",TRUE)} -> IVV | F19: {=_FV(A19,"Hora da última transação",TRUE)} -> 46322.671 | G19: {=_FV(A19,"Variação")} -> 5.38 | H19: {=_FV(A19,"Variação (%)",TRUE)} -> 0.006999 | I19: {=_FV(tb_acoes[[#This Row],[Ações]],"Moeda")} -> USD | J19: #VALUE! | K19: {=IFERROR(_FV(J19,"Preço"),"")} -> 5.3414 | L19: {=IFERROR(_FV(J19,"Da moeda",TRUE),"")} -> USD | M19: {=IFERROR(_FV(J19,"Moeda"),"")} -> BRL

Sheet Planilha1
A1: Campo calculado
A2: Ordem de resolução | B2: Campo | C2: Fórmula
A3: 1 | B3: Campo1 | C3: = ('VALOR TOTAL MERCADO'-'VALOR TOTAL')/'VALOR TOTAL'
A4: 2 | B4: Campo2 | C4: ='VALOR TOTAL MERCADO' -'VALOR TOTAL'
A6: Item calculado
A7: Ordem de resolução | B7: Item | C7: Fórmula
A10: Observação: | B10: Quando uma célula é atualizada por mais de uma fórmula,
B11: o valor é definido pela fórmula com a última ordem de resolução.
B13: Para alterar a ordem de resolução de vários itens ou campos calculados,
B14: na guia Opções, no grupo Cálculos, clique em Campos, Itens e Conjuntos e clique em Ordem de Resolução.

Sheet RESUMO
B2: TIPO MOVIMENTAÇÃO | C2: Aporte
B3: FEITO? | C3: SIM
D4: R$ | E4: R$ | F4: R$ | G4: R$ | H4: R$ | I4: % | J4: %
B5: # | C5: COTAS | D5: PREÇO NEGOCIADO | E5: PREÇO MERCADO | F5: TOTAL NEGOCIADO | G5: TOTAL MERCADO | H5: GANHO/ PERDA | I5: VALORIZAÇÂO | J5: VARIAÇÃO REAL
B6: Ações | C6: 24 | D6: 22.476433 | E6: 20.622667 | F6: 427.79 | G6: 395.22 | H6: -32.57 | I6: -0.076135487 | J6: 0.0047438
B7: BBAS3 | C7: 4 | D7: 19.0425 | E7: 17.76 | F7: 76.17 | G7: 71.04 | H7: -5.13 | I7: -0.06734935 | J7: 0.0166
B8: BBSE3 | C8: 1 | D8: 41.77 | E8: 43.52 | F8: 41.77 | G8: 43.52 | H8: 1.75 | I8: 0.041896098 | J8: 0.008809
B9: EQTL3 | C9: 3 | D9: 40.853333 | E9: 35.54 | F9: 122.56 | G9: 106.62 | H9: -15.94 | I9: -0.13005875 | J9: 0.020092
B10: ITSA3 | C10: 4 | D10: 13.9275 | E10: 13.9 | F10: 55.71 | G10: 55.6 | H10: -0.11 | I10: -0.0019745109 | J10: -0.014184
B11: SAPR4 | C11: 10 | D11: 7.291 | E11: 6.72 | F11: 72.91 | G11: 67.2 | H11: -5.71 | I11: -0.078315732 | J11: -0.011765
B12: SBSP3 | C12: 2 | D12: 29.335 | E12: 25.62 | F12: 58.67 | G12: 51.24 | H12: -7.43 | I12: -0.12664053 | J12: 0.01385
B13: FIIs | C13: 33 | D13: #DIV/0! | E13: 43.252381 | F13: #DIV/0! | G13: 367.67 | H13: -4.34 | I13: -0.011666353 | J13: -0.015502333
B14: GARE11 | C14: 10 | D14: 8.473 | E14: 8.35 | F14: 84.73 | G14: 83.5 | H14: -1.23 | I14: -0.0145167 | J14: -0.044622
B15: KNSC11 | C15: 8 | D15: 8.98 | E15: 8.91 | F15: 71.84 | G15: 71.28 | H15: -0.56 | I15: -0.0077951002 | J15: -0.007795
B16: MXRF11 | C16: 14 | D16: 9.1778571 | E16: 9.01 | F16: 128.49 | G16: 126.14 | H16: -2.35 | I16: -0.018289361 | J16: -0.010977
B17: XPLG11 | D17: #DIV/0! | E17: 92.32 | F17: #DIV/0! | G17: 0 | H17: 0 | I17: #DIV/0! | J17: -0.008591
B18: HGLG11 | D18: #DIV/0! | E18: 149.68 | F18: #DIV/0! | G18: 0 | H18: 0 | I18: #DIV/0! | J18: -0.013316
B19: KNRI11 | D19: #DIV/0! | E19: 152.64 | F19: #DIV/0! | G19: 0 | H19: 0 | I19: #DIV/0! | J19: -0.005279
B20: BTLG11 | D20: #DIV/0! | E20: 98.99 | F20: #DIV/0! | G20: 0 | H20: 0 | I20: #DIV/0! | J20: -0.011583
B21: XPML11 | D21: #DIV/0! | E21: 99.91 | F21: #DIV/0! | G21: 0 | H21: 0 | I21: #DIV/0! | J21: -0.002894
B22: KNCA11 | C22: 1 | D22: 86.95 | E22: 86.75 | F22: 86.95 | G22: 86.75 | H22: -0.2 | I22: -0.0023001725 | J22: -0.014205
B23: KNCR11 | D23: #DIV/0! | E23: 104.91 | F23: #DIV/0! | G23: 0 | H23: 0 | I23: #DIV/0! | J23: 0.005849
B24: Total Geral | C24: 57 | D24: #DIV/0! | E24: 33.823333 | F24: #DIV/0! | G24: 762.89 | H24: -36.91 | I24: -0.046149037 | J24: -0.0070664444

Sheet planejamento financeiro
A3: Soma de VALOR TOTAL | B3: Rótulos de Coluna
A4: Rótulos de Linha | B4: Entradas | C4: Saídas | D4: Aporte | E4: Resultado | F4: %
A5: 2026 | B5: 32230 | C5: 12672.393 | D5: 4799.8 | E5: =B5-C5 -> 19557.607 | F5: =(1-(C5/B5)) -> 0.60681375
A6: out | D6: 799.8
A7: nov | B7: 18820 | C7: 6834.2084 | D7: 2000 | E7: =B7-C7 -> 11985.792 | F7: =(1-(C7/B7)) -> 0.63686459
A8: dez | B8: 13410 | C8: 5838.1844 | D8: 2000 | E8: =B8-C8 -> 7571.8156 | F8: =(1-(C8/B8)) -> 0.5646395
A9: 2027 | B9: 106310 | C9: 46468.516 | D9: 34000 | E9: =B9-C9 -> 59841.484 | F9: =(1-(C9/B9)) -> 0.56289609
A10: jan | B10: 13410 | C10: 4678.6835 | D10: 2500 | E10: =B10-C10 -> 8731.3165 | F10: =(1-(C10/B10)) -> 0.65110488
A11: fev | B11: 8700 | C11: 3457.6941 | D11: 2500 | E11: =B11-C11 -> 5242.3059 | F11: =(1-(C11/B11)) -> 0.6025639
A12: mar | B12: 8700 | C12: 3523.2151 | D12: 2500 | E12: =B12-C12 -> 5176.7849 | F12: =(1-(C12/B12)) -> 0.59503275
A13: abr | B13: 8700 | C13: 3586.2248 | D13: 2500 | E13: =B13-C13 -> 5113.7752 | F13: =(1-(C13/B13)) -> 0.58779025
A14: mai | B14: 8700 | C14: 3649.2241 | D14: 2500 | E14: =B14-C14 -> 5050.7759 | F14: =(1-(C14/B14)) -> 0.58054895
A15: jun | B15: 8700 | C15: 3703.8249 | D15: 2500 | E15: =B15-C15 -> 4996.1751 | F15: =(1-(C15/B15)) -> 0.574273
A16: jul | B16: 8700 | C16: 3758.4361 | D16: 2500 | E16: =B16-C16 -> 4941.5639 | F16: =(1-(C16/B16)) -> 0.56799585
A17: ago | B17: 8700 | C17: 3313.0369 | D17: 2500 | E17: =B17-C17 -> 5386.9631 | F17: =(1-(C17/B17)) -> 0.61919116
A18: set | B18: 8000 | C18: 4367.6377 | D18: 3500 | E18: =B18-C18 -> 3632.3623 | F18: =(1-(C18/B18)) -> 0.45404528
A19: out | B19: 8000 | C19: 3422.2385 | D19: 3500 | E19: =B19-C19 -> 4577.7615 | F19: =(1-(C19/B19)) -> 0.57222018
A20: nov | B20: 8000 | C20: 4476.8498 | D20: 3500 | E20: =B20-C20 -> 3523.1502 | F20: =(1-(C20/B20)) -> 0.44039378
A21: dez | B21: 8000 | C21: 4531.4506 | D21: 3500 | E21: =B21-C21 -> 3468.5494 | F21: =(1-(C21/B21)) -> 0.43356868
A22: 2028 | B22: 96000 | C22: 25846.937 | D22: 46000 | E22: =B22-C22 -> 70153.063 | F22: =(1-(C22/B22)) -> 0.73076107
A23: jan | B23: 8000 | C23: 1869.9521 | D23: 4000 | E23: =B23-C23 -> 6130.0479 | F23: =(1-(C23/B23)) -> 0.76625599
A24: fev | B24: 8000 | C24: 1920.3536 | D24: 4000 | E24: =B24-C24 -> 6079.6464 | F24: =(1-(C24/B24)) -> 0.75995579
A25: mar | B25: 8000 | C25: 1968.244 | D25: 4000 | E25: =B25-C25 -> 6031.756 | F25: =(1-(C25/B25)) -> 0.7539695
A26: abr | B26: 8000 | C26: 2015.2798 | D26: 4000 | E26: =B26-C26 -> 5984.7202 | F26: =(1-(C26/B26)) -> 0.74809002
A27: mai | B27: 8000 | C27: 2040.4858 | D27: 4000 | E27: =B27-C27 -> 5959.5142 | F27: =(1-(C27/B27)) -> 0.74493927
A28: jun | B28: 8000 | C28: 2065.6814 | D28: 4000 | E28: =B28-C28 -> 5934.3186 | F28: =(1-(C28/B28)) -> 0.74178983
A29: jul | B29: 8000 | C29: 2090.8874 | D29: 4000 | E29: =B29-C29 -> 5909.1126 | F29: =(1-(C29/B29)) -> 0.73863908
A30: ago | B30: 8000 | C30: 2110.8874 | D30: 4000 | E30: =B30-C30 -> 5889.1126 | F30: =(1-(C30/B30)) -> 0.73613908
A31: set | B31: 8000 | C31: 2116.0933 | D31: 4000 | E31: =B31-C31 -> 5883.9067 | F31: =(1-(C31/B31)) -> 0.73548833
A32: out | B32: 8000 | C32: 2532.8904 | D32: 4000 | E32: =B32-C32 -> 5467.1096 | F32: =(1-(C32/B32)) -> 0.6833887
A33: nov | B33: 8000 | C33: 2549.6874 | D33: 3000 | E33: =B33-C33 -> 5450.3126 | F33: =(1-(C33/B33)) -> 0.68128907
A34: dez | B34: 8000 | C34: 2566.4949 | D34: 3000 | E34: =B34-C34 -> 5433.5051 | F34: =(1-(C34/B34)) -> 0.67918814
A35: 2029 | B35: 96000 | C35: 33192.965 | D35: 36000 | E35: =B35-C35 -> 62807.035 | F35: =(1-(C35/B35)) -> 0.65423995
A36: jan | B36: 8000 | C36: 2583.2919 | D36: 3000 | E36: =B36-C36 -> 5416.7081 | F36: =(1-(C36/B36)) -> 0.67708851
A37: fev | B37: 8000 | C37: 2600.089 | D37: 3000 | E37: =B37-C37 -> 5399.911 | F37: =(1-(C37/B37)) -> 0.67498888
A38: mar | B38: 8000 | C38: 2616.8964 | D38: 3000 | E38: =B38-C38 -> 5383.1036 | F38: =(1-(C38/B38)) -> 0.67288795
A39: abr | B39: 8000 | C39: 2617.0631 | D39: 3000 | E39: =B39-C39 -> 5382.9369 | F39: =(1-(C39/B39)) -> 0.67286711
A40: mai | B40: 8000 | C40: 2847.0013 | D40: 3000 | E40: =B40-C40 -> 5152.9987 | F40: =(1-(C40/B40)) -> 0.64412484
A41: jun | B41: 8000 | C41: 2846.9909 | D41: 3000 | E41: =B41-C41 -> 5153.0091 | F41: =(1-(C41/B41)) -> 0.64412614
A42: jul | B42: 8000 | C42: 2846.9804 | D42: 3000 | E42: =B42-C42 -> 5153.0196 | F42: =(1-(C42/B42)) -> 0.64412744
...

Sheet Base de dados
G2: SUM | H2: AVERAGE | J2: SUM
G3: =SUBTOTAL(109,G5:G1048576) -> 1 | H3: =SUBTOTAL(1,H5:H1048576) -> 86.95 | J3: =SUBTOTAL(109,J5:J1048576) -> 86.95 | Q3: =SUBTOTAL(1,Q5:Q1048576) -> 86.67 | R3: =SUBTOTAL(109,R5:R1048576) -> 86.67 | S3: =SUBTOTAL(109,S5:S1048576) -> -0.28 | T3: =SUBTOTAL(1,T5:T1048576) -> -0.015114 | U3: =SUBTOTAL(1,U5:U1048576) -> -0.0032202415
B4: TIPO MOVIMENTAÇÃO | C4: DATA | D4: DESCRIÇÃO | E4: MOEDA | F4: ATIVO | G4: QUANTIDADE | H4: PREÇO | I4: CORRETORA/BANCO | J4: VALOR TOTAL | K4: FEITO? | L4: Mês | M4: Ano | N4: Dia | O4: PREÇO MÉDIO PONDERADO | P4: VALOR TOTAL PONDERADO | Q4: PREÇO MERCADO | R4: VALOR TOTAL MERCADO | S4: GANHO/PERDA | T4: VARIAÇÃO (%) | U4: VALORIZAÇÃO (%)
B5: Aporte | C5: 46302 | D5: GARE11 | E5: =IF(tb_investimentos[[#This Row],[TIPO MOVIMENTAÇÃO]]="Aporte",_xlfn.XLOOKUP(tb_investimentos[[#This Row],[DESCRIÇÃO]],'INFO AÇÕES'!E:E,'INFO AÇÕES'!I:I),"BRL") -> BRL | F5: FIIs | G5: 1 | H5: 8.74 | I5: Investimentos BB | J5: =H5*G5 -> 8.74 | K5: SIM | L5: =MONTH(tb_investimentos[[#This Row],[DATA]]) -> 10 | M5: =YEAR(tb_investimentos[[#This Row],[DATA]]) -> 2026 | N5: =DAY(tb_investimentos[[#This Row],[DATA]]) -> 7 | O5: =SUMIF($D$5:$D$10000, D5, $J$5:$J$10000) / SUMIF($D$5:$D$10000, D5, $G$5:$G$10000) -> 8.473 | P5: =tb_investimentos[[#This Row],[PREÇO MÉDIO PONDERADO]]*tb_investimentos[[#This Row],[QUANTIDADE]] -> 8.473 | Q5: =IFERROR(_xlfn.XLOOKUP(tb_investimentos[[#This Row],[DESCRIÇÃO]],tb_acoes[Símbolo do ticker],tb_acoes[Preço]),"") -> 8.35 | R5: =IFERROR(tb_investimentos[[#This Row],[QUANTIDADE]]*tb_investimentos[[#This Row],[PREÇO MERCADO]],"") -> 8.35 | S5: =IFERROR(tb_investimentos[[#This Row],[VALOR TOTAL MERCADO]]-tb_investimentos[[#This Row],[VALOR TOTAL PONDERADO]],"") -> -0.123 | T5: =IFERROR(_xlfn.XLOOKUP(tb_investimentos[[#This Row],[DESCRIÇÃO]],'INFO AÇÕES'!E:E,'INFO AÇÕES'!H:H),"") -> -0.044622 | U5: =IFERROR((tb_investimentos[[#This Row],[VALOR TOTAL MERCADO]]-tb_investimentos[[#This Row],[VALOR TOTAL PONDERADO]])/tb_investimentos[[#This Row],[VALOR TOTAL PONDERADO]],"") -> -0.0145167
B6: Aporte | C6: 46302 | D6: MXRF11 | E6: =IF(tb_investimentos[[#This Row],[TIPO MOVIMENTAÇÃO]]="Aporte",_xlfn.XLOOKUP(tb_investimentos[[#This Row],[DESCRIÇÃO]],'INFO AÇÕES'!E:E,'INFO AÇÕES'!I:I),"BRL") -> BRL | F6: FIIs | G6: 1 | H6: 9.38 | I6: Investimentos BB | J6: =H6*G6 -> 9.38 | K6: SIM | L6: =MONTH(tb_investimentos[[#This Row],[DATA]]) -> 10 | M6: =YEAR(tb_investimentos[[#This Row],[DATA]]) -> 2026 | N6: =DAY(tb_investimentos[[#This Row],[DATA]]) -> 7 | O6: =SUMIF($D$5:$D$10000, D6, $J$5:$J$10000) / SUMIF($D$5:$D$10000, D6, $G$5:$G$10000) -> 9.1778571 | P6: =tb_investimentos[[#This Row],[PREÇO MÉDIO PONDERADO]]*tb_investimentos[[#This Row],[QUANTIDADE]] -> 9.1778571 | Q6: =IFERROR(_xlfn.XLOOKUP(tb_investimentos[[#This Row],[DESCRIÇÃO]],tb_acoes[Símbolo do ticker],tb_acoes[Preço]),"") -> 9.02 | R6: =IFERROR(tb_investimentos[[#This Row],[QUANTIDADE]]*tb_investimentos[[#This Row],[PREÇO MERCADO]],"") -> 9.02 | S6: =IFERROR(tb_investimentos[[#This Row],[VALOR TOTAL MERCADO]]-tb_investimentos[[#This Row],[VALOR TOTAL PONDERADO]],"") -> -0.15785714 | T6: =IFERROR(_xlfn.XLOOKUP(tb_investimentos[[#This Row],[DESCRIÇÃO]],'INFO AÇÕES'!E:E,'INFO AÇÕES'!H:H),"") -> -0.009879 | U6: =IFERROR((tb_investimentos[[#This Row],[VALOR TOTAL MERCADO]]-tb_investimentos[[#This Row],[VALOR TOTAL PONDERADO]])/tb_investimentos[[#This Row],[VALOR TOTAL PONDERADO]],"") -> -0.017199782
B7: Aporte | C7: 46302 | D7: MXRF11 | E7: =IF(tb_investimentos[[#This Row],[TIPO MOVIMENTAÇÃO]]="Aporte",_xlfn.XLOOKUP(tb_investimentos[[#This Row],[DESCRIÇÃO]],'INFO AÇÕES'!E:E,'INFO AÇÕES'!I:I),"BRL") -> BRL | F7: FIIs | G7: 1 | H7: 9.44 | I7: Investimentos BB | J7: =H7*G7 -> 9.44 | K7: SIM | L7: =MONTH(tb_investimentos[[#This Row],[DATA]]) -> 10 | M7: =YEAR(tb_investimentos[[#This Row],[DATA]]) -> 2026 | N7: =DAY(tb_investimentos[[#This Row],[DATA]]) -> 7 | O7: =SUMIF($D$5:$D$10000, D7, $J$5:$J$10000) / SUMIF($D$5:$D$10000, D7, $G$5:$G$10000) -> 9.1778571 | P7: =tb_investimentos[[#This Row],[PREÇO MÉDIO PONDERADO]]*tb_investimentos[[#This Row],[QUANTIDADE]] -> 9.1778571 | Q7: =IFERROR(_xlfn.XLOOKUP(tb_investimentos[[#This Row],[DESCRIÇÃO]],tb_acoes[Símbolo do ticker],tb_acoes[Preço]),"") -> 9.02 | R7: =IFERROR(tb_investimentos[[#This Row],[QUANTIDADE]]*tb_investimentos[[#This Row],[PREÇO MERCADO]],"") -> 9.02 | S7: =IFERROR(tb_investimentos[[#This Row],[VALOR TOTAL MERCADO]]-tb_investimentos[[#This Row],[VALOR TOTAL PONDERADO]],"") -> -0.15785714 | T7: =IFERROR(_xlfn.XLOOKUP(tb_investimentos[[#This Row],[DESCRIÇÃO]],'INFO AÇÕES'!E:E,'INFO AÇÕES'!H:H),"") -> -0.009879 | U7: =IFERROR((tb_investimentos[[#This Row],[VALOR TOTAL MERCADO]]-tb_investimentos[[#This Row],[VALOR TOTAL PONDERADO]])/tb_investimentos[[#This Row],[VALOR TOTAL PONDERADO]],"") -> -0.017199782
B8: Aporte | C8: 46309 | D8: KNSC11 | E8: =IF(tb_investimentos[[#This Row],[TIPO MOVIMENTAÇÃO]]="Aporte",_xlfn.XLOOKUP(tb_investimentos[[#This Row],[DESCRIÇÃO]],'INFO AÇÕES'!E:E,'INFO AÇÕES'!I:I),"BRL") -> BRL | F8: FIIs | G8: 3 | H8: 9.07 | I8: Investimentos BB | J8: =H8*G8 -> 27.21 | K8: SIM | L8: =MONTH(tb_investimentos[[#This Row],[DATA]]) -> 10 | M8: =YEAR(tb_investimentos[[#This Row],[DATA]]) -> 2026 | N8: =DAY(tb_investimentos[[#This Row],[DATA]]) -> 14 | O8: =SUMIF($D$5:$D$10000, D8, $J$5:$J$10000) / SUMIF($D$5:$D$10000, D8, $G$5:$G$10000) -> 8.98 | P8: =tb_investimentos[[#This Row],[PREÇO MÉDIO PONDERADO]]*tb_investimentos[[#This Row],[QUANTIDADE]] -> 26.94 | Q8: =IFERROR(_xlfn.XLOOKUP(tb_investimentos[[#This Row],[DESCRIÇÃO]],tb_acoes[Símbolo do ticker],tb_acoes[Preço]),"") -> 8.85 | R8: =IFERROR(tb_investimentos[[#This Row],[QUANTIDADE]]*tb_investimentos[[#This Row],[PREÇO MERCADO]],"") -> 26.55 | S8: =IFERROR(tb_investimentos[[#This Row],[VALOR TOTAL MERCADO]]-tb_investimentos[[#This Row],[VALOR TOTAL PONDERADO]],"") -> -0.39 | T8: =IFERROR(_xlfn.XLOOKUP(tb_investimentos[[#This Row],[DESCRIÇÃO]],'INFO AÇÕES'!E:E,'INFO AÇÕES'!H:H),"") -> -0.014477 | U8: =IFERROR((tb_investimentos[[#This Row],[VALOR TOTAL MERCADO]]-tb_investimentos[[#This Row],[VALOR TOTAL PONDERADO]])/tb_investimentos[[#This Row],[VALOR TOTAL PONDERADO]],"") -> -0.014476615
B9: Aporte | C9: 46309 | D9: MXRF11 | E9: =IF(tb_investimentos[[#This Row],[TIPO MOVIMENTAÇÃO]]="Aporte",_xlfn.XLOOKUP(tb_investimentos[[#This Row],[DESCRIÇÃO]],'INFO AÇÕES'!E:E,'INFO AÇÕES'!I:I),"BRL") -> BRL | F9: FIIs | G9: 3 | H9: 9.32 | I9: Investimentos BB | J9: =H9*G9 -> 27.96 | K9: SIM | L9: =MONTH(tb_investimentos[[#This Row],[DATA]]) -> 10 | M9: =YEAR(tb_investimentos[[#This Row],[DATA]]) -> 2026 | N9: =DAY(tb_investimentos[[#This Row],[DATA]]) -> 14 | O9: =SUMIF($D$5:$D$10000, D9, $J$5:$J$10000) / SUMIF($D$5:$D$10000, D9, $G$5:$G$10000) -> 9.1778571 | P9: =tb_investimentos[[#This Row],[PREÇO MÉDIO PONDERADO]]*tb_investimentos[[#This Row],[QUANTIDADE]] -> 27.533571 | Q9: =IFERROR(_xlfn.XLOOKUP(tb_investimentos[[#This Row],[DESCRIÇÃO]],tb_acoes[Símbolo do ticker],tb_acoes[Preço]),"") -> 9.02 | R9: =IFERROR(tb_investimentos[[#This Row],[QUANTIDADE]]*tb_investimentos[[#This Row],[PREÇO MERCADO]],"") -> 27.06 | S9: =IFERROR(tb_investimentos[[#This Row],[VALOR TOTAL MERCADO]]-tb_investimentos[[#This Row],[VALOR TOTAL PONDERADO]],"") -> -0.47357143 | T9: =IFERROR(_xlfn.XLOOKUP(tb_investimentos[[#This Row],[DESCRIÇÃO]],'INFO AÇÕES'!E:E,'INFO AÇÕES'!H:H),"") -> -0.009879 | U9: =IFERROR((tb_investimentos[[#This Row],[VALOR TOTAL MERCADO]]-tb_investimentos[[#This Row],[VALOR TOTAL PONDERADO]])/tb_investimentos[[#This Row],[VALOR TOTAL PONDERADO]],"") -> -0.017199782
B10: Aporte | C10: 46309 | D10: GARE11 | E10: =IF(tb_investimentos[[#This Row],[TIPO MOVIMENTAÇÃO]]="Aporte",_xlfn.XLOOKUP(tb_investimentos[[#This Row],[DESCRIÇÃO]],'INFO AÇÕES'!E:E,'INFO AÇÕES'!I:I),"BRL") -> BRL | F10: FIIs | G10: 2 | H10: 8.59 | I10: Investimentos BB | J10: =H10*G10 -> 17.18 | K10: SIM | L10: =MONTH(tb_investimentos[[#This Row],[DATA]]) -> 10 | M10: =YEAR(tb_investimentos[[#This Row],[DATA]]) -> 2026 | N10: =DAY(tb_investimentos[[#This Row],[DATA]]) -> 14 | O10: =SUMIF($D$5:$D$10000, D10, $J$5:$J$10000) / SUMIF($D$5:$D$10000, D10, $G$5:$G$10000) -> 8.473 | P10: =tb_investimentos[[#This Row],[PREÇO MÉDIO PONDERADO]]*tb_investimentos[[#This Row],[QUANTIDADE]] -> 16.946 | Q10: =IFERROR(_xlfn.XLOOKUP(tb_investimentos[[#This Row],[DESCRIÇÃO]],tb_acoes[Símbolo do ticker],tb_acoes[Preço]),"") -> 8.35 | R10: =IFERROR(tb_investimentos[[#This Row],[QUANTIDADE]]*tb_investimentos[[#This Row],[PREÇO MERCADO]],"") -> 16.7 | S10: =IFERROR(tb_investimentos[[#This Row],[VALOR TOTAL MERCADO]]-tb_investimentos[[#This Row],[VALOR TOTAL PONDERADO]],"") -> -0.246 | T10: =IFERROR(_xlfn.XLOOKUP(tb_investimentos[[#This Row],[DESCRIÇÃO]],'INFO AÇÕES'!E:E,'INFO AÇÕES'!H:H),"") -> -0.044622 | U10: =IFERROR((tb_investimentos[[#This Row],[VALOR TOTAL MERCADO]]-tb_investimentos[[#This Row],[VALOR TOTAL PONDERADO]])/tb_investimentos[[#This Row],[VALOR TOTAL PONDERADO]],"") -> -0.0145167
B11: Aporte | C11: 46309 | D11: SAPR4 | E11: =IF(tb_investimentos[[#This Row],[TIPO MOVIMENTAÇÃO]]="Aporte",_xlfn.XLOOKUP(tb_investimentos[[#This Row],[DESCRIÇÃO]],'INFO AÇÕES'!E:E,'INFO AÇÕES'!I:I),"BRL") -> BRL | F11: Ações | G11: 2 | H11: 7.84 | I11: Investimentos BB | J11: =H11*G11 -> 15.68 | K11: SIM | L11: =MONTH(tb_investimentos[[#This Row],[DATA]]) -> 10 | M11: =YEAR(tb_investimentos[[#This Row],[DATA]]) -> 2026 | N11: =DAY(tb_investimentos[[#This Row],[DATA]]) -> 14 | O11: =SUMIF($D$5:$D$10000, D11, $J$5:$J$10000) / SUMIF($D$5:$D$10000, D11, $G$5:$G$10000) -> 7.291 | P11: =tb_investimentos[[#This Row],[PREÇO MÉDIO PONDERADO]]*tb_investimentos[[#This Row],[QUANTIDADE]] -> 14.582 | Q11: =IFERROR(_xlfn.XLOOKUP(tb_investimentos[[#This Row],[DESCRIÇÃO]],tb_acoes[Símbolo do ticker],tb_acoes[Preço]),"") -> 6.86 | R11: =IFERROR(tb_investimentos[[#This Row],[QUANTIDADE]]*tb_investimentos[[#This Row],[PREÇO MERCADO]],"") -> 13.72 | S11: =IFERROR(tb_investimentos[[#This Row],[VALOR TOTAL MERCADO]]-tb_investimentos[[#This Row],[VALOR TOTAL PONDERADO]],"") -> -0.862 | T11: =IFERROR(_xlfn.XLOOKUP(tb_investimentos[[#This Row],[DESCRIÇÃO]],'INFO AÇÕES'!E:E,'INFO AÇÕES'!H:H),"") -> 0.008824 | U11: =IFERROR((tb_investimentos[[#This Row],[VALOR TOTAL MERCADO]]-tb_investimentos[[#This Row],[VALOR TOTAL PONDERADO]])/tb_investimentos[[#This Row],[VALOR TOTAL PONDERADO]],"") -> -0.059113976
B12: Aporte | C12: 46314 | D12: GARE11 | E12: =IF(tb_investimentos[[#This Row],[TIPO MOVIMENTAÇÃO]]="Aporte",_xlfn.XLOOKUP(tb_investimentos[[#This Row],[DESCRIÇÃO]],'INFO AÇÕES'!E:E,'INFO AÇÕES'!I:I),"BRL") -> BRL | F12: FIIs | G12: 2 | H12: 8.68 | I12: Investimentos BB | J12: =H12*G12 -> 17.36 | K12: SIM | L12: =MONTH(tb_investimentos[[#This Row],[DATA]]) -> 10 | M12: =YEAR(tb_investimentos[[#This Row],[DATA]]) -> 2026 | N12: =DAY(tb_investimentos[[#This Row],[DATA]]) -> 19 | O12: =SUMIF($D$5:$D$10000, D12, $J$5:$J$10000) / SUMIF($D$5:$D$10000, D12, $G$5:$G$10000) -> 8.473 | P12: =tb_investimentos[[#This Row],[PREÇO MÉDIO PONDERADO]]*tb_investimentos[[#This Row],[QUANTIDADE]] -> 16.946 | Q12: =IFERROR(_xlfn.XLOOKUP(tb_investimentos[[#This Row],[DESCRIÇÃO]],tb_acoes[Símbolo do ticker],tb_acoes[Preço]),"") -> 8.35 | R12: =IFERROR(tb_investimentos[[#This Row],[QUANTIDADE]]*tb_investimentos[[#This Row],[PREÇO MERCADO]],"") -> 16.7 | S12: =IFERROR(tb_investimentos[[#This Row],[VALOR TOTAL MERCADO]]-tb_investimentos[[#This Row],[VALOR TOTAL PONDERADO]],"") -> -0.246 | T12: =IFERROR(_xlfn.XLOOKUP(tb_investimentos[[#This Row],[DESCRIÇÃO]],'INFO AÇÕES'!E:E,'INFO AÇÕES'!H:H),"") -> -0.044622 | U12: =IFERROR((tb_investimentos[[#This Row],[VALOR TOTAL MERCADO]]-tb_investimentos[[#This Row],[VALOR TOTAL PONDERADO]])/tb_investimentos[[#This Row],[VALOR TOTAL PONDERADO]],"") -> -0.0145167
B13: Aporte | C13: 46314 | D13: KNSC11 | E13: =IF(tb_investimentos[[#This Row],[TIPO MOVIMENTAÇÃO]]="Aporte",_xlfn.XLOOKUP(tb_investimentos[[#This Row],[DESCRIÇÃO]],'INFO AÇÕES'!E:E,'INFO AÇÕES'!I:I),"BRL") -> BRL | F13: FIIs | G13: 2 | H13: 9.16 | I13: Investimentos BB | J13: =H13*G13 -> 18.32 | K13: SIM | L13: =MONTH(tb_investimentos[[#This Row],[DATA]]) -> 10 | M13: =YEAR(tb_investimentos[[#This Row],[DATA]]) -> 2026 | N13: =DAY(tb_investimentos[[#This Row],[DATA]]) -> 19 | O13: =SUMIF($D$5:$D$10000, D13, $J$5:$J$10000) / SUMIF($D$5:$D$10000, D13, $G$5:$G$10000) -> 8.98 | P13: =tb_investimentos[[#This Row],[PREÇO MÉDIO PONDERADO]]*tb_investimentos[[#This Row],[QUANTIDADE]] -> 17.96 | Q13: =IFERROR(_xlfn.XLOOKUP(tb_investimentos[[#This Row],[DESCRIÇÃO]],tb_acoes[Símbolo do ticker],tb_acoes[Preço]),"") -> 8.85 | R13: =IFERROR(tb_investimentos[[#This Row],[QUANTIDADE]]*tb_investimentos[[#This Row],[PREÇO MERCADO]],"") -> 17.7 | S13: =IFERROR(tb_investimentos[[#This Row],[VALOR TOTAL MERCADO]]-tb_investimentos[[#This Row],[VALOR TOTAL PONDERADO]],"") -> -0.26 | T13: =IFERROR(_xlfn.XLOOKUP(tb_investimentos[[#This Row],[DESCRIÇÃO]],'INFO AÇÕES'!E:E,'INFO AÇÕES'!H:H),"") -> -0.014477 | U13: =IFERROR((tb_investimentos[[#This Row],[VALOR TOTAL MERCADO]]-tb_investimentos[[#This Row],[VALOR TOTAL PONDERADO]])/tb_investimentos[[#This Row],[VALOR TOTAL PONDERADO]],"") -> -0.014476615
B14: Aporte | C14: 46314 | D14: MXRF11 | E14: =IF(tb_investimentos[[#This Row],[TIPO MOVIMENTAÇÃO]]="Aporte",_xlfn.XLOOKUP(tb_investimentos[[#This Row],[DESCRIÇÃO]],'INFO AÇÕES'!E:E,'INFO AÇÕES'!I:I),"BRL") -> BRL | F14: FIIs | G14: 2 | H14: 9.39 | I14: Investimentos BB | J14: =H14*G14 -> 18.78 | K14: SIM | L14: =MONTH(tb_investimentos[[#This Row],[DATA]]) -> 10 | M14: =YEAR(tb_investimentos[[#This Row],[DATA]]) -> 2026 | N14: =DAY(tb_investimentos[[#This Row],[DATA]]) -> 19 | O14: =SUMIF($D$5:$D$10000, D14, $J$5:$J$10000) / SUMIF($D$5:$D$10000, D14, $G$5:$G$10000) -> 9.1778571 | P14: =tb_investimentos[[#This Row],[PREÇO MÉDIO PONDERADO]]*tb_investimentos[[#This Row],[QUANTIDADE]] -> 18.355714 | Q14: =IFERROR(_xlfn.XLOOKUP(tb_investimentos[[#This Row],[DESCRIÇÃO]],tb_acoes[Símbolo do ticker],tb_acoes[Preço]),"") -> 9.02 | R14: =IFERROR(tb_investimentos[[#This Row],[QUANTIDADE]]*tb_investimentos[[#This Row],[PREÇO MERCADO]],"") -> 18.04 | S14: =IFERROR(tb_investimentos[[#This Row],[VALOR TOTAL MERCADO]]-tb_investimentos[[#This Row],[VALOR TOTAL PONDERADO]],"") -> -0.31571429 | T14: =IFERROR(_xlfn.XLOOKUP(tb_investimentos[[#This Row],[DESCRIÇÃO]],'INFO AÇÕES'!E:E,'INFO AÇÕES'!H:H),"") -> -0.009879 | U14: =IFERROR((tb_investimentos[[#This Row],[VALOR TOTAL MERCADO]]-tb_investimentos[[#This Row],[VALOR TOTAL PONDERADO]])/tb_investimentos[[#This Row],[VALOR TOTAL PONDERADO]],"") -> -0.017199782
B15: Aporte | C15: 46314 | D15: SAPR4 | E15: =IF(tb_investimentos[[#This Row],[TIPO MOVIMENTAÇÃO]]="Aporte",_xlfn.XLOOKUP(tb_investimentos[[#This Row],[DESCRIÇÃO]],'INFO AÇÕES'!E:E,'INFO AÇÕES'!I:I),"BRL") -> BRL | F15: Ações | G15: 3 | H15: 7.75 | I15: Investimentos BB | J15: =H15*G15 -> 23.25 | K15: SIM | L15: =MONTH(tb_investimentos[[#This Row],[DATA]]) -> 10 | M15: =YEAR(tb_investimentos[[#This Row],[DATA]]) -> 2026 | N15: =DAY(tb_investimentos[[#This Row],[DATA]]) -> 19 | O15: =SUMIF($D$5:$D$10000, D15, $J$5:$J$10000) / SUMIF($D$5:$D$10000, D15, $G$5:$G$10000) -> 7.291 | P15: =tb_investimentos[[#This Row],[PREÇO MÉDIO PONDERADO]]*tb_investimentos[[#This Row],[QUANTIDADE]] -> 21.873 | Q15: =IFERROR(_xlfn.XLOOKUP(tb_investimentos[[#This Row],[DESCRIÇÃO]],tb_acoes[Símbolo do ticker],tb_acoes[Preço]),"") -> 6.86 | R15: =IFERROR(tb_investimentos[[#This Row],[QUANTIDADE]]*tb_investimentos[[#This Row],[PREÇO MERCADO]],"") -> 20.58 | S15: =IFERROR(tb_investimentos[[#This Row],[VALOR TOTAL MERCADO]]-tb_investimentos[[#This Row],[VALOR TOTAL PONDERADO]],"") -> -1.293 | T15: =IFERROR(_xlfn.XLOOKUP(tb_investimentos[[#This Row],[DESCRIÇÃO]],'INFO AÇÕES'!E:E,'INFO AÇÕES'!H:H),"") -> 0.008824 | U15: =IFERROR((tb_investimentos[[#This Row],[VALOR TOTAL MERCADO]]-tb_investimentos[[#This Row],[VALOR TOTAL PONDERADO]])/tb_investimentos[[#This Row],[VALOR TOTAL PONDERADO]],"") -> -0.059113976
B16: Aporte | C16: 46314 | D16: ITSA3 | E16: =IF(tb_investimentos[[#This Row],[TIPO MOVIMENTAÇÃO]]="Aporte",_xlfn.XLOOKUP(tb_investimentos[[#This Row],[DESCRIÇÃO]],'INFO AÇÕES'!E:E,'INFO AÇÕES'!I:I),"BRL") -> BRL | F16: Ações | G16: 1 | H16: 15.42 | I16: Investimentos BB | J16: =H16*G16 -> 15.42 | K16: SIM | L16: =MONTH(tb_investimentos[[#This Row],[DATA]]) -> 10 | M16: =YEAR(tb_investimentos[[#This Row],[DATA]]) -> 2026 | N16: =DAY(tb_investimentos[[#This Row],[DATA]]) -> 19 | O16: =SUMIF($D$5:$D$10000, D16, $J$5:$J$10000) / SUMIF($D$5:$D$10000, D16, $G$5:$G$10000) -> 13.9275 | P16: =tb_investimentos[[#This Row],[PREÇO MÉDIO PONDERADO]]*tb_investimentos[[#This Row],[QUANTIDADE]] -> 13.9275 | Q16: =IFERROR(_xlfn.XLOOKUP(tb_investimentos[[#This Row],[DESCRIÇÃO]],tb_acoes[Símbolo do ticker],tb_acoes[Preço]),"") -> 13.97 | R16: =IFERROR(tb_investimentos[[#This Row],[QUANTIDADE]]*tb_investimentos[[#This Row],[PREÇO MERCADO]],"") -> 13.97 | S16: =IFERROR(tb_investimentos[[#This Row],[VALOR TOTAL MERCADO]]-tb_investimentos[[#This Row],[VALOR TOTAL PONDERADO]],"") -> 0.0425 | T16: =IFERROR(_xlfn.XLOOKUP(tb_investimentos[[#This Row],[DESCRIÇÃO]],'INFO AÇÕES'!E:E,'INFO AÇÕES'!H:H),"") -> -0.00922 | U16: =IFERROR((tb_investimentos[[#This Row],[VALOR TOTAL MERCADO]]-tb_investimentos[[#This Row],[VALOR TOTAL PONDERADO]])/tb_investimentos[[#This Row],[VALOR TOTAL PONDERADO]],"") -> 0.0030515168
... B26: Saídas | C26: 46331 | D26: Banco do Brasil | E26: =IF(tb_investimentos[[#This Row],[TIPO MOVIMENTAÇÃO]]="Aporte",_xlfn.XLOOKUP(tb_investimentos[[#This Row],[DESCRIÇÃO]],'INFO AÇÕES'!E:E,'INFO AÇÕES'!I:I),"BRL") -> BRL | F26: Cartão de Crédito | G26: 1 | H26: 1150 | I26: Banco do Brasil | J26: =H26*G26 -> 1150 | K26: NÃO | L26: =MONTH(tb_investimentos[[#This Row],[DATA]]) -> 11 | M26: =YEAR(tb_investimentos[[#This Row],[DATA]]) -> 2026 | N26: =DAY(tb_investimentos[[#This Row],[DATA]]) -> 5 | O26: =SUMIF($D$5:$D$10000, D26, $J$5:$J$10000) / SUMIF($D$5:$D$10000, D26, $G$5:$G$10000) -> 515.93333 | P26: =tb_investimentos[[#This Row],[PREÇO MÉDIO PONDERADO]]*tb_investimentos[[#This Row],[QUANTIDADE]] -> 515.93333 | Q26: =IFERROR(_xlfn.XLOOKUP(tb_investimentos[[#This Row],[DESCRIÇÃO]],tb_acoes[Símbolo do ticker],tb_acoes[Preço]),"") | R26: =IFERROR(tb_investimentos[[#This Row],[QUANTIDADE]]*tb_investimentos[[#This Row],[PREÇO MERCADO]],"") | S26: =IFERROR(tb_investimentos[[#This Row],[VALOR TOTAL MERCADO]]-tb_investimentos[[#This Row],[VALOR TOTAL PONDERADO]],"") | T26: =IFERROR(_xlfn.XLOOKUP(tb_investimentos[[#This Row],[DESCRIÇÃO]],'INFO AÇÕES'!E:E,'INFO AÇÕES'!H:H),"") | U26: =IFERROR((tb_investimentos[[#This Row],[VALOR TOTAL MERCADO]]-tb_investimentos[[#This Row],[VALOR TOTAL PONDERADO]])/tb_investimentos[[#This Row],[VALOR TOTAL PONDERADO]],"")
B27: Aporte | C27: 46331 | E27: =IF(tb_investimentos[[#This Row],[TIPO MOVIMENTAÇÃO]]="Aporte",_xlfn.XLOOKUP(tb_investimentos[[#This Row],[DESCRIÇÃO]],'INFO AÇÕES'!E:E,'INFO AÇÕES'!I:I),"BRL") -> 0 | F27: Ações | G27: 1 | H27: 2000 | I27: Investimentos BB | J27: =H27*G27 -> 2000 | K27: NÃO | L27: =MONTH(tb_investimentos[[#This Row],[DATA]]) -> 11 | M27: =YEAR(tb_investimentos[[#This Row],[DATA]]) -> 2026 | N27: =DAY(tb_investimentos[[#This Row],[DATA]]) -> 5 | O27: =SUMIF($D$5:$D$10000, D27, $J$5:$J$10000) / SUMIF($D$5:$D$10000, D27, $G$5:$G$10000) -> #DIV/0! | P27: =tb_investimentos[[#This Row],[PREÇO MÉDIO PONDERADO]]*tb_investimentos[[#This Row],[QUANTIDADE]] -> #DIV/0! | Q27: =IFERROR(_xlfn.XLOOKUP(tb_investimentos[[#This Row],[DESCRIÇÃO]],tb_acoes[Símbolo do ticker],tb_acoes[Preço]),"") | R27: =IFERROR(tb_investimentos[[#This Row],[QUANTIDADE]]*tb_investimentos[[#This Row],[PREÇO MERCADO]],"") | S27: =IFERROR(tb_investimentos[[#This Row],[VALOR TOTAL MERCADO]]-tb_investimentos[[#This Row],[VALOR TOTAL PONDERADO]],"") | T27: =IFERROR(_xlfn.XLOOKUP(tb_investimentos[[#This Row],[DESCRIÇÃO]],'INFO AÇÕES'!E:E,'INFO AÇÕES'!H:H),"") | U27: =IFERROR((tb_investimentos[[#This Row],[VALOR TOTAL MERCADO]]-tb_investimentos[[#This Row],[VALOR TOTAL PONDERADO]])/tb_investimentos[[#This Row],[VALOR TOTAL PONDERADO]],"")
B28: Saídas | C28: 46332 | D28: Mercado Livre | E28: =IF(tb_investimentos[[#This Row],[TIPO MOVIMENTAÇÃO]]="Aporte",_xlfn.XLOOKUP(tb_investimentos[[#This Row],[DESCRIÇÃO]],'INFO AÇÕES'!E:E,'INFO AÇÕES'!I:I),"BRL") -> BRL | F28: Emprestimo 1/3 | G28: 1 | H28: 650 | I28: Banco do Brasil | J28: =H28*G28 -> 650 | K28: NÃO | L28: =MONTH(tb_investimentos[[#This Row],[DATA]]) -> 11 | M28: =YEAR(tb_investimentos[[#This Row],[DATA]]) -> 2026 | N28: =DAY(tb_investimentos[[#This Row],[DATA]]) -> 6 | O28: =SUMIF($D$5:$D$10000, D28, $J$5:$J$10000) / SUMIF($D$5:$D$10000, D28, $G$5:$G$10000) -> 650 | P28: =tb_investimentos[[#This Row],[PREÇO MÉDIO PONDERADO]]*tb_investimentos[[#This Row],[QUANTIDADE]] -> 650 | Q28: =IFERROR(_xlfn.XLOOKUP(tb_investimentos[[#This Row],[DESCRIÇÃO]],tb_acoes[Símbolo do ticker],tb_acoes[Preço]),"") | R28: =IFERROR(tb_investimentos[[#This Row],[QUANTIDADE]]*tb_investimentos[[#This Row],[PREÇO MERCADO]],"") | S28: =IFERROR(tb_investimentos[[#This Row],[VALOR TOTAL MERCADO]]-tb_investimentos[[#This Row],[VALOR TOTAL PONDERADO]],"") | T28: =IFERROR(_xlfn.XLOOKUP(tb_investimentos[[#This Row],[DESCRIÇÃO]],'INFO AÇÕES'!E:E,'INFO AÇÕES'!H:H),"") | U28: =IFERROR((tb_investimentos[[#This Row],[VALOR TOTAL MERCADO]]-tb_investimentos[[#This Row],[VALOR TOTAL PONDERADO]])/tb_investimentos[[#This Row],[VALOR TOTAL PONDERADO]],"")
B29: Entradas | C29: 46332 | D29: Capital de Giro | E29: =IF(tb_investimentos[[#This Row],[TIPO MOVIMENTAÇÃO]]="Aporte",_xlfn.XLOOKUP(tb_investimentos[[#This Row],[DESCRIÇÃO]],'INFO AÇÕES'!E:E,'INFO AÇÕES'!I:I),"BRL") -> BRL | F29: Pascoal | G29: 1 | H29: 4710 | I29: Banco do Brasil | J29: =H29*G29 -> 4710 | K29: NÃO | L29: =MONTH(tb_investimentos[[#This Row],[DATA]]) -> 11 | M29: =YEAR(tb_investimentos[[#This Row],[DATA]]) -> 2026 | N29: =DAY(tb_investimentos[[#This Row],[DATA]]) -> 6 | O29: =SUMIF($D$5:$D$10000, D29, $J$5:$J$10000) / SUMIF($D$5:$D$10000, D29, $G$5:$G$10000) -> 4710 | P29: =tb_investimentos[[#This Row],[PREÇO MÉDIO PONDERADO]]*tb_investimentos[[#This Row],[QUANTIDADE]] -> 4710 | Q29: =IFERROR(_xlfn.XLOOKUP(tb_investimentos[[#This Row],[DESCRIÇÃO]],tb_acoes[Símbolo do ticker],tb_acoes[Preço]),"") | R29: =IFERROR(tb_investimentos[[#This Row],[QUANTIDADE]]*tb_investimentos[[#This Row],[PREÇO MERCADO]],"") | S29: =IFERROR(tb_investimentos[[#This Row],[VALOR TOTAL MERCADO]]-tb_investimentos[[#This Row],[VALOR TOTAL PONDERADO]],"") | T29: =IFERROR(_xlfn.XLOOKUP(tb_investimentos[[#This Row],[DESCRIÇÃO]],'INFO AÇÕES'!E:E,'INFO AÇÕES'!H:H),"") | U29: =IFERROR((tb_investimentos[[#This Row],[VALOR TOTAL MERCADO]]-tb_investimentos[[#This Row],[VALOR TOTAL PONDERADO]])/tb_investimentos[[#This Row],[VALOR TOTAL PONDERADO]],"")
B30: Entradas | C30: 46332 | D30: Capital de Giro | E30: =IF(tb_investimentos[[#This Row],[TIPO MOVIMENTAÇÃO]]="Aporte",_xlfn.XLOOKUP(tb_investimentos[[#This Row],[DESCRIÇÃO]],'INFO AÇÕES'!E:E,'INFO AÇÕES'!I:I),"BRL") -> BRL | F30: Pascoal | G30: 1 | H30: 4710 | I30: Banco do Brasil | J30: =H30*G30 -> 4710 | K30: NÃO | L30: =MONTH(tb_investimentos[[#This Row],[DATA]]) -> 11 | M30: =YEAR(tb_investimentos[[#This Row],[DATA]]) -> 2026 | N30: =DAY(tb_investimentos[[#This Row],[DATA]]) -> 6 | O30: =SUMIF($D$5:$D$10000, D30, $J$5:$J$10000) / SUMIF($D$5:$D$10000, D30, $G$5:$G$10000) -> 4710 | P30: =tb_investimentos[[#This Row],[PREÇO MÉDIO PONDERADO]]*tb_investimentos[[#This Row],[QUANTIDADE]] -> 4710 | Q30: =IFERROR(_xlfn.XLOOKUP(tb_investimentos[[#This Row],[DESCRIÇÃO]],tb_acoes[Símbolo do ticker],tb_acoes[Preço]),"") | R30: =IFERROR(tb_investimentos[[#This Row],[QUANTIDADE]]*tb_investimentos[[#This Row],[PREÇO MERCADO]],"") | S30: =IFERROR(tb_investimentos[[#This Row],[VALOR TOTAL MERCADO]]-tb_investimentos[[#This Row],[VALOR TOTAL PONDERADO]],"") | T30: =IFERROR(_xlfn.XLOOKUP(tb_investimentos[[#This Row],[DESCRIÇÃO]],'INFO AÇÕES'!E:E,'INFO AÇÕES'!H:H),"") | U30: =IFERROR((tb_investimentos[[#This Row],[VALOR TOTAL MERCADO]]-tb_investimentos[[#This Row],[VALOR TOTAL PONDERADO]])/tb_investimentos[[#This Row],[VALOR TOTAL PONDERADO]],"")
B31: Saídas | C31: 46334 | D31: Sabesp | E31: =IF(tb_investimentos[[#This Row],[TIPO MOVIMENTAÇÃO]]="Aporte",_xlfn.XLOOKUP(tb_investimentos[[#This Row],[DESCRIÇÃO]],'INFO AÇÕES'!E:E,'INFO AÇÕES'!I:I),"BRL") -> BRL | F31: Agua | G31: 1 | H31: 25 | I31: Banco do Brasil | J31: =H31*G31 -> 25 | K31: NÃO | L31: =MONTH(tb_investimentos[[#This Row],[DATA]]) -> 11 | M31: =YEAR(tb_investimentos[[#This Row],[DATA]]) -> 2026 | N31: =DAY(tb_investimentos[[#This Row],[DATA]]) -> 8 | O31: =SUMIF($D$5:$D$10000, D31, $J$5:$J$10000) / SUMIF($D$5:$D$10000, D31, $G$5:$G$10000) -> 25 | P31: =tb_investimentos[[#This Row],[PREÇO MÉDIO PONDERADO]]*tb_investimentos[[#This Row],[QUANTIDADE]] -> 25 | Q31: =IFERROR(_xlfn.XLOOKUP(tb_investimentos[[#This Row],[DESCRIÇÃO]],tb_acoes[Símbolo do ticker],tb_acoes[Preço]),"") | R31: =IFERROR(tb_investimentos[[#This Row],[QUANTIDADE]]*tb_investimentos[[#This Row],[PREÇO MERCADO]],"") | S31: =IFERROR(tb_investimentos[[#This Row],[VALOR TOTAL MERCADO]]-tb_investimentos[[#This Row],[VALOR TOTAL PONDERADO]],"") | T31: =IFERROR(_xlfn.XLOOKUP(tb_investimentos[[#This Row],[DESCRIÇÃO]],'INFO AÇÕES'!E:E,'INFO AÇÕES'!H:H),"") | U31: =IFERROR((tb_investimentos[[#This Row],[VALOR TOTAL MERCADO]]-tb_investimentos[[#This Row],[VALOR TOTAL PONDERADO]])/tb_investimentos[[#This Row],[VALOR TOTAL PONDERADO]],"")
B32: Saídas | C32: 46336 | D32: Cia Manah | E32: =IF(tb_investimentos[[#This Row],[TIPO MOVIMENTAÇÃO]]="Aporte",_xlfn.XLOOKUP(tb_investimentos[[#This Row],[DESCRIÇÃO]],'INFO AÇÕES'!E:E,'INFO AÇÕES'!I:I),"BRL") -> BRL | F32: Ballet e Ginastica | G32: 1 | H32: 95 | I32: Banco do Brasil | J32: =H32*G32 -> 95 | K32: NÃO | L32: =MONTH(tb_investimentos[[#This Row],[DATA]]) -> 11 | M32: =YEAR(tb_investimentos[[#This Row],[DATA]]) -> 2026 | N32: =DAY(tb_investimentos[[#This Row],[DATA]]) -> 10 | O32: =SUMIF($D$5:$D$10000, D32, $J$5:$J$10000) / SUMIF($D$5:$D$10000, D32, $G$5:$G$10000) -> 95 | P32: =tb_investimentos[[#This Row],[PREÇO MÉDIO PONDERADO]]*tb_investimentos[[#This Row],[QUANTIDADE]] -> 95 | Q32: =IFERROR(_xlfn.XLOOKUP(tb_investimentos[[#This Row],[DESCRIÇÃO]],tb_acoes[Símbolo do ticker],tb_acoes[Preço]),"") | R32: =IFERROR(tb_investimentos[[#This Row],[QUANTIDADE]]*tb_investimentos[[#This Row],[PREÇO MERCADO]],"") | S32: =IFERROR(tb_investimentos[[#This Row],[VALOR TOTAL MERCADO]]-tb_investimentos[[#This Row],[VALOR TOTAL PONDERADO]],"") | T32: =IFERROR(_xlfn.XLOOKUP(tb_investimentos[[#This Row],[DESCRIÇÃO]],'INFO AÇÕES'!E:E,'INFO AÇÕES'!H:H),"") | U32: =IFERROR((tb_investimentos[[#This Row],[VALOR TOTAL MERCADO]]-tb_investimentos[[#This Row],[VALOR TOTAL PONDERADO]])/tb_investimentos[[#This Row],[VALOR TOTAL PONDERADO]],"")
B33: Saídas | C33: 46338 | D33: Youtube | E33: =IF(tb_investimentos[[#This Row],[TIPO MOVIMENTAÇÃO]]="Aporte",_xlfn.XLOOKUP(tb_investimentos[[#This Row],[DESCRIÇÃO]],'INFO AÇÕES'!E:E,'INFO AÇÕES'!I:I),"BRL") -> BRL | F33: Youtube Music | G33: 1 | H33: 16.9 | I33: Banco do Brasil | J33: =H33*G33 -> 16.9 | K33: NÃO | L33: =MONTH(tb_investimentos[[#This Row],[DATA]]) -> 11 | M33: =YEAR(tb_investimentos[[#This Row],[DATA]]) -> 2026 | N33: =DAY(tb_investimentos[[#This Row],[DATA]]) -> 12 | O33: =SUMIF($D$5:$D$10000, D33, $J$5:$J$10000) / SUMIF($D$5:$D$10000, D33, $G$5:$G$10000) -> 137.33454 | P33: =tb_investimentos[[#This Row],[PREÇO MÉDIO PONDERADO]]*tb_investimentos[[#This Row],[QUANTIDADE]] -> 137.33454 | Q33: =IFERROR(_xlfn.XLOOKUP(tb_investimentos[[#This Row],[DESCRIÇÃO]],tb_acoes[Símbolo do ticker],tb_acoes[Preço]),"") | R33: =IFERROR(tb_investimentos[[#This Row],[QUANTIDADE]]*tb_investimentos[[#This Row],[PREÇO MERCADO]],"") | S33: =IFERROR(tb_investimentos[[#This Row],[VALOR TOTAL MERCADO]]-tb_investimentos[[#This Row],[VALOR TOTAL PONDERADO]],"") | T33: =IFERROR(_xlfn.XLOOKUP(tb_investimentos[[#This Row],[DESCRIÇÃO]],'INFO AÇÕES'!E:E,'INFO AÇÕES'!H:H),"") | U33: =IFERROR((tb_investimentos[[#This Row],[VALOR TOTAL MERCADO]]-tb_investimentos[[#This Row],[VALOR TOTAL PONDERADO]])/tb_investimentos[[#This Row],[VALOR TOTAL PONDERADO]],"")
B34: Saídas | C34: 46341 | D34: Vivo | E34: =IF(tb_investimentos[[#This Row],[TIPO MOVIMENTAÇÃO]]="Aporte",_xlfn.XLOOKUP(tb_investimentos[[#This Row],[DESCRIÇÃO]],'INFO AÇÕES'!E:E,'INFO AÇÕES'!I:I),"BRL") -> BRL | F34: Movel | G34: 1 | H34: 39.9 | I34: Banco do Brasil | J34: =H34*G34 -> 39.9 | K34: NÃO | L34: =MONTH(tb_investimentos[[#This Row],[DATA]]) -> 11 | M34: =YEAR(tb_investimentos[[#This Row],[DATA]]) -> 2026 | N34: =DAY(tb_investimentos[[#This Row],[DATA]]) -> 15 | O34: =SUMIF($D$5:$D$10000, D34, $J$5:$J$10000) / SUMIF($D$5:$D$10000, D34, $G$5:$G$10000) -> 59.9 | P34: =tb_investimentos[[#This Row],[PREÇO MÉDIO PONDERADO]]*tb_investimentos[[#This Row],[QUANTIDADE]] -> 59.9 | Q34: =IFERROR(_xlfn.XLOOKUP(tb_investimentos[[#This Row],[DESCRIÇÃO]],tb_acoes[Símbolo do ticker],tb_acoes[Preço]),"") | R34: =IFERROR(tb_investimentos[[#This Row],[QUANTIDADE]]*tb_investimentos[[#This Row],[PREÇO MERCADO]],"") | S34: =IFERROR(tb_investimentos[[#This Row],[VALOR TOTAL MERCADO]]-tb_investimentos[[#This Row],[VALOR TOTAL PONDERADO]],"") | T34: =IFERROR(_xlfn.XLOOKUP(tb_investimentos[[#This Row],[DESCRIÇÃO]],'INFO AÇÕES'!E:E,'INFO AÇÕES'!H:H),"") | U34: =IFERROR((tb_investimentos[[#This Row],[VALOR TOTAL MERCADO]]-tb_investimentos[[#This Row],[VALOR TOTAL PONDERADO]])/tb_investimentos[[#This Row],[VALOR TOTAL PONDERADO]],"")
B35: Saídas | C35: 46341 | D35: Vivo | E35: =IF(tb_investimentos[[#This Row],[TIPO MOVIMENTAÇÃO]]="Aporte",_xlfn.XLOOKUP(tb_investimentos[[#This Row],[DESCRIÇÃO]],'INFO AÇÕES'!E:E,'INFO AÇÕES'!I:I),"BRL") -> BRL | F35: Fibra | G35: 1 | H35: 79.9 | I35: Banco do Brasil | J35: =H35*G35 -> 79.9 | K35: NÃO | L35: =MONTH(tb_investimentos[[#This Row],[DATA]]) -> 11 | M35: =YEAR(tb_investimentos[[#This Row],[DATA]]) -> 2026 | N35: =DAY(tb_investimentos[[#This Row],[DATA]]) -> 15 | O35: =SUMIF($D$5:$D$10000, D35, $J$5:$J$10000) / SUMIF($D$5:$D$10000, D35, $G$5:$G$10000) -> 59.9 | P35: =tb_investimentos[[#This Row],[PREÇO MÉDIO PONDERADO]]*tb_investimentos[[#This Row],[QUANTIDADE]] -> 59.9 | Q35: =IFERROR(_xlfn.XLOOKUP(tb_investimentos[[#This Row],[DESCRIÇÃO]],tb_acoes[Símbolo do ticker],tb_acoes[Preço]),"") | R35: =IFERROR(tb_investimentos[[#This Row],[QUANTIDADE]]*tb_investimentos[[#This Row],[PREÇO MERCADO]],"") | S35: =IFERROR(tb_investimentos[[#This Row],[VALOR TOTAL MERCADO]]-tb_investimentos[[#This Row],[VALOR TOTAL PONDERADO]],"") | T35: =IFERROR(_xlfn.XLOOKUP(tb_investimentos[[#This Row],[DESCRIÇÃO]],'INFO AÇÕES'!E:E,'INFO AÇÕES'!H:H),"") | U35: =IFERROR((tb_investimentos[[#This Row],[VALOR TOTAL MERCADO]]-tb_investimentos[[#This Row],[VALOR TOTAL PONDERADO]])/tb_investimentos[[#This Row],[VALOR TOTAL PONDERADO]],"")
B36: Saídas | C36: 46341 | D36: Enel | E36: =IF(tb_investimentos[[#This Row],[TIPO MOVIMENTAÇÃO]]="Aporte",_xlfn.XLOOKUP(tb_investimentos[[#This Row],[DESCRIÇÃO]],'INFO AÇÕES'!E:E,'INFO AÇÕES'!I:I),"BRL") -> BRL | F36: Energia | G36: 1 | H36: 110 | I36: Banco do Brasil | J36: =H36*G36 -> 110 | K36: NÃO | L36: =MONTH(tb_investimentos[[#This Row],[DATA]]) -> 11 | M36: =YEAR(tb_investimentos[[#This Row],[DATA]]) -> 2026 | N36: =DAY(tb_investimentos[[#This Row],[DATA]]) -> 15 | O36: =SUMIF($D$5:$D$10000, D36, $J$5:$J$10000) / SUMIF($D$5:$D$10000, D36, $G$5:$G$10000) -> 110 | P36: =tb_investimentos[[#This Row],[PREÇO MÉDIO PONDERADO]]*tb_investimentos[[#This Row],[QUANTIDADE]] -> 110 | Q36: =IFERROR(_xlfn.XLOOKUP(tb_investimentos[[#This Row],[DESCRIÇÃO]],tb_acoes[Símbolo do ticker],tb_acoes[Preço]),"") | R36: =IFERROR(tb_investimentos[[#This Row],[QUANTIDADE]]*tb_investimentos[[#This Row],[PREÇO MERCADO]],"") | S36: =IFERROR(tb_investimentos[[#This Row],[VALOR TOTAL MERCADO]]-tb_investimentos[[#This Row],[VALOR TOTAL PONDERADO]],"") | T36: =IFERROR(_xlfn.XLOOKUP(tb_investimentos[[#This Row],[DESCRIÇÃO]],'INFO AÇÕES'!E:E,'INFO AÇÕES'!H:H),"") | U36: =IFERROR((tb_investimentos[[#This Row],[VALOR TOTAL MERCADO]]-tb_investimentos[[#This Row],[VALOR TOTAL PONDERADO]])/tb_investimentos[[#This Row],[VALOR TOTAL PONDERADO]],"")
B37: Saídas | C37: 46341 | D37: Contabilizei | E37: =IF(tb_investimentos[[#This Row],[TIPO MOVIMENTAÇÃO]]="Aporte",_xlfn.XLOOKUP(tb_investimentos[[#This Row],[DESCRIÇÃO]],'INFO AÇÕES'!E:E,'INFO AÇÕES'!I:I),"BRL") -> BRL | F37: Impostos | G37: 1 | H37: 500 | I37: Banco do Brasil | J37: =H37*G37 -> 500 | K37: NÃO | L37: =MONTH(tb_investimentos[[#This Row],[DATA]]) -> 11 | M37: =YEAR(tb_investimentos[[#This Row],[DATA]]) -> 2026 | N37: =DAY(tb_investimentos[[#This Row],[DATA]]) -> 15 | O37: =SUMIF($D$5:$D$10000, D37, $J$5:$J$10000) / SUMIF($D$5:$D$10000, D37, $G$5:$G$10000) -> 500 | P37: =tb_investimentos[[#This Row],[PREÇO MÉDIO PONDERADO]]*tb_investimentos[[#This Row],[QUANTIDADE]] -> 500 | Q37: =IFERROR(_xlfn.XLOOKUP(tb_investimentos[[#This Row],[DESCRIÇÃO]],tb_acoes[Símbolo do ticker],tb_acoes[Preço]),"") | R37: =IFERROR(tb_investimentos[[#This Row],[QUANTIDADE]]*tb_investimentos[[#This Row],[PREÇO MERCADO]],"") | S37: =IFERROR(tb_investimentos[[#This Row],[VALOR TOTAL MERCADO]]-tb_investimentos[[#This Row],[VALOR TOTAL PONDERADO]],"") | T37: =IFERROR(_xlfn.XLOOKUP(tb_investimentos[[#This Row],[DESCRIÇÃO]],'INFO AÇÕES'!E:E,'INFO AÇÕES'!H:H),"") | U37: =IFERROR((tb_investimentos[[#This Row],[VALOR TOTAL MERCADO]]-tb_investimentos[[#This Row],[VALOR TOTAL PONDERADO]])/tb_investimentos[[#This Row],[VALOR TOTAL PONDERADO]],"")
B38: Saídas | C38: 46341 | D38: Caixa Econômica Federal | E38: =IF(tb_investimentos[[#This Row],[TIPO MOVIMENTAÇÃO]]="Aporte",_xlfn.XLOOKUP(tb_investimentos[[#This Row],[DESCRIÇÃO]],'INFO AÇÕES'!E:E,'INFO AÇÕES'!I:I),"BRL") -> BRL | F38: Evolução de obras | G38: 1 | H38: 742.50836 | I38: Banco do Brasil | J38: =H38*G38 -> 742.50836 | K38: NÃO | L38: =MONTH(tb_investimentos[[#This Row],[DATA]]) -> 11 | M38: =YEAR(tb_investimentos[[#This Row],[DATA]]) -> 2026 | N38: =DAY(tb_investimentos[[#This Row],[DATA]]) -> 15 | O38: =SUMIF($D$5:$D$10000, D38, $J$5:$J$10000) / SUMIF($D$5:$D$10000, D38, $G$5:$G$10000) -> 1629.993 | P38: =tb_investimentos[[#This Row],[PREÇO MÉDIO PONDERADO]]*tb_investimentos[[#This Row],[QUANTIDADE]] -> 1629.993 | Q38: =IFERROR(_xlfn.XLOOKUP(tb_investimentos[[#This Row],[DESCRIÇÃO]],tb_acoes[Símbolo do ticker],tb_acoes[Preço]),"") | R38: =IFERROR(tb_investimentos[[#This Row],[QUANTIDADE]]*tb_investimentos[[#This Row],[PREÇO MERCADO]],"") | S38: =IFERROR(tb_investimentos[[#This Row],[VALOR TOTAL MERCADO]]-tb_investimentos[[#This Row],[VALOR TOTAL PONDERADO]],"") | T38: =IFERROR(_xlfn.XLOOKUP(tb_investimentos[[#This Row],[DESCRIÇÃO]],'INFO AÇÕES'!E:E,'INFO AÇÕES'!H:H),"") | U38: =IFERROR((tb_investimentos[[#This Row],[VALOR TOTAL MERCADO]]-tb_investimentos[[#This Row],[VALOR TOTAL PONDERADO]])/tb_investimentos[[#This Row],[VALOR TOTAL PONDERADO]],"")
B39: Saídas | C39: 46346 | D39: DAS/DARF | E39: =IF(tb_investimentos[[#This Row],[TIPO MOVIMENTAÇÃO]]="Aporte",_xlfn.XLOOKUP(tb_investimentos[[#This Row],[DESCRIÇÃO]],'INFO AÇÕES'!E:E,'INFO AÇÕES'!I:I),"BRL") -> BRL | F39: Impostos | G39: 1 | H39: 87 | I39: Banco do Brasil | J39: =H39*G39 -> 87 | K39: NÃO | L39: =MONTH(tb_investimentos[[#This Row],[DATA]]) -> 11 | M39: =YEAR(tb_investimentos[[#This Row],[DATA]]) -> 2026 | N39: =DAY(tb_investimentos[[#This Row],[DATA]]) -> 20 | O39: =SUMIF($D$5:$D$10000, D39, $J$5:$J$10000) / SUMIF($D$5:$D$10000, D39, $G$5:$G$10000) -> 93.857143 | P39: =tb_investimentos[[#This Row],[PREÇO MÉDIO PONDERADO]]*tb_investimentos[[#This Row],[QUANTIDADE]] -> 93.857143 | Q39: =IFERROR(_xlfn.XLOOKUP(tb_investimentos[[#This Row],[DESCRIÇÃO]],tb_acoes[Símbolo do ticker],tb_acoes[Preço]),"") | R39: =IFERROR(tb_investimentos[[#This Row],[QUANTIDADE]]*tb_investimentos[[#This Row],[PREÇO MERCADO]],"") | S39: =IFERROR(tb_investimentos[[#This Row],[VALOR TOTAL MERCADO]]-tb_investimentos[[#This Row],[VALOR TOTAL PONDERADO]],"") | T39: =IFERROR(_xlfn.XLOOKUP(tb_investimentos[[#This Row],[DESCRIÇÃO]],'INFO AÇÕES'!E:E,'INFO AÇÕES'!H:H),"") | U39: =IFERROR((tb_investimentos[[#This Row],[VALOR TOTAL MERCADO]]-tb_investimentos[[#This Row],[VALOR TOTAL PONDERADO]])/tb_investimentos[[#This Row],[VALOR TOTAL PONDERADO]],"")
... B47: Saídas | C47: 46361 | D47: Banco do Brasil | E47: =IF(tb_investimentos[[#This Row],[TIPO MOVIMENTAÇÃO]]="Aporte",_xlfn.XLOOKUP(tb_investimentos[[#This Row],[DESCRIÇÃO]],'INFO AÇÕES'!E:E,'INFO AÇÕES'!I:I),"BRL") -> BRL | F47: Cartão de Crédito | G47: 1 | H47: 500 | I47: Banco do Brasil | J47: =H47*G47 -> 500 | K47: NÃO | L47: =MONTH(tb_investimentos[[#This Row],[DATA]]) -> 12 | M47: =YEAR(tb_investimentos[[#This Row],[DATA]]) -> 2026 | N47: =DAY(tb_investimentos[[#This Row],[DATA]]) -> 5 | O47: =SUMIF($D$5:$D$10000, D47, $J$5:$J$10000) / SUMIF($D$5:$D$10000, D47, $G$5:$G$10000) -> 515.93333 | P47: =tb_investimentos[[#This Row],[PREÇO MÉDIO PONDERADO]]*tb_investimentos[[#This Row],[QUANTIDADE]] -> 515.93333 | Q47: =IFERROR(_xlfn.XLOOKUP(tb_investimentos[[#This Row],[DESCRIÇÃO]],tb_acoes[Símbolo do ticker],tb_acoes[Preço]),"") | R47: =IFERROR(tb_investimentos[[#This Row],[QUANTIDADE]]*tb_investimentos[[#This Row],[PREÇO MERCADO]],"") | S47: =IFERROR(tb_investimentos[[#This Row],[VALOR TOTAL MERCADO]]-tb_investimentos[[#This Row],[VALOR TOTAL PONDERADO]],"") | T47: =IFERROR(_xlfn.XLOOKUP(tb_investimentos[[#This Row],[DESCRIÇÃO]],'INFO AÇÕES'!E:E,'INFO AÇÕES'!H:H),"") | U47: =IFERROR((tb_investimentos[[#This Row],[VALOR TOTAL MERCADO]]-tb_investimentos[[#This Row],[VALOR TOTAL PONDERADO]])/tb_investimentos[[#This Row],[VALOR TOTAL PONDERADO]],"")
B48: Aporte | C48: 46361 | E48: =IF(tb_investimentos[[#This Row],[TIPO MOVIMENTAÇÃO]]="Aporte",_xlfn.XLOOKUP(tb_investimentos[[#This Row],[DESCRIÇÃO]],'INFO AÇÕES'!E:E,'INFO AÇÕES'!I:I),"BRL") -> 0 | F48: Ações | G48: 1 | H48: 2000 | I48: Investimentos BB | J48: =H48*G48 -> 2000 | K48: NÃO | L48: =MONTH(tb_investimentos[[#This Row],[DATA]]) -> 12 | M48: =YEAR(tb_investimentos[[#This Row],[DATA]]) -> 2026 | N48: =DAY(tb_investimentos[[#This Row],[DATA]]) -> 5 | O48: =SUMIF($D$5:$D$10000, D48, $J$5:$J$10000) / SUMIF($D$5:$D$10000, D48, $G$5:$G$10000) -> #DIV/0! | P48: =tb_investimentos[[#This Row],[PREÇO MÉDIO PONDERADO]]*tb_investimentos[[#This Row],[QUANTIDADE]] -> #DIV/0! | Q48: =IFERROR(_xlfn.XLOOKUP(tb_investimentos[[#This Row],[DESCRIÇÃO]],tb_acoes[Símbolo do ticker],tb_acoes[Preço]),"") | R48: =IFERROR(tb_investimentos[[#This Row],[QUANTIDADE]]*tb_investimentos[[#This Row],[PREÇO MERCADO]],"") | S48: =IFERROR(tb_investimentos[[#This Row],[VALOR TOTAL MERCADO]]-tb_investimentos[[#This Row],[VALOR TOTAL PONDERADO]],"") | T48: =IFERROR(_xlfn.XLOOKUP(tb_investimentos[[#This Row],[DESCRIÇÃO]],'INFO AÇÕES'!E:E,'INFO AÇÕES'!H:H),"") | U48: =IFERROR((tb_investimentos[[#This Row],[VALOR TOTAL MERCADO]]-tb_investimentos[[#This Row],[VALOR TOTAL PONDERADO]])/tb_investimentos[[#This Row],[VALOR TOTAL PONDERADO]],"")
B49: Saídas | C49: 46362 | D49: Mercado Livre | E49: =IF(tb_investimentos[[#This Row],[TIPO MOVIMENTAÇÃO]]="Aporte",_xlfn.XLOOKUP(tb_investimentos[[#This Row],[DESCRIÇÃO]],'INFO AÇÕES'!E:E,'INFO AÇÕES'!I:I),"BRL") -> BRL | F49: Emprestimo 2/3 | G49: 1 | H49: 650 | I49: Banco do Brasil | J49: =H49*G49 -> 650 | K49: NÃO | L49: =MONTH(tb_investimentos[[#This Row],[DATA]]) -> 12 | M49: =YEAR(tb_investimentos[[#This Row],[DATA]]) -> 2026 | N49: =DAY(tb_investimentos[[#This Row],[DATA]]) -> 6 | O49: =SUMIF($D$5:$D$10000, D49, $J$5:$J$10000) / SUMIF($D$5:$D$10000, D49, $G$5:$G$10000) -> 650 | P49: =tb_investimentos[[#This Row],[PREÇO MÉDIO PONDERADO]]*tb_investimentos[[#This Row],[QUANTIDADE]] -> 650 | Q49: =IFERROR(_xlfn.XLOOKUP(tb_investimentos[[#This Row],[DESCRIÇÃO]],tb_acoes[Símbolo do ticker],tb_acoes[Preço]),"") | R49: =IFERROR(tb_investimentos[[#This Row],[QUANTIDADE]]*tb_investimentos[[#This Row],[PREÇO MERCADO]],"") | S49: =IFERROR(tb_investimentos[[#This Row],[VALOR TOTAL MERCADO]]-tb_investimentos[[#This Row],[VALOR TOTAL PONDERADO]],"") | T49: =IFERROR(_xlfn.XLOOKUP(tb_investimentos[[#This Row],[DESCRIÇÃO]],'INFO AÇÕES'!E:E,'INFO AÇÕES'!H:H),"") | U49: =IFERROR((tb_investimentos[[#This Row],[VALOR TOTAL MERCADO]]-tb_investimentos[[#This Row],[VALOR TOTAL PONDERADO]])/tb_investimentos[[#This Row],[VALOR TOTAL PONDERADO]],"")
B50: Entradas | C50: 46362 | D50: Capital de Giro | E50: =IF(tb_investimentos[[#This Row],[TIPO MOVIMENTAÇÃO]]="Aporte",_xlfn.XLOOKUP(tb_investimentos[[#This Row],[DESCRIÇÃO]],'INFO AÇÕES'!E:E,'INFO AÇÕES'!I:I),"BRL") -> BRL | F50: Pascoal | G50: 1 | H50: 4710 | I50: Banco do Brasil | J50: =H50*G50 -> 4710 | K50: NÃO | L50: =MONTH(tb_investimentos[[#This Row],[DATA]]) -> 12 | M50: =YEAR(tb_investimentos[[#This Row],[DATA]]) -> 2026 | N50: =DAY(tb_investimentos[[#This Row],[DATA]]) -> 6 | O50: =SUMIF($D$5:$D$10000, D50, $J$5:$J$10000) / SUMIF($D$5:$D$10000, D50, $G$5:$G$10000) -> 4710 | P50: =tb_investimentos[[#This Row],[PREÇO MÉDIO PONDERADO]]*tb_investimentos[[#This Row],[QUANTIDADE]] -> 4710 | Q50: =IFERROR(_xlfn.XLOOKUP(tb_investimentos[[#This Row],[DESCRIÇÃO]],tb_acoes[Símbolo do ticker],tb_acoes[Preço]),"") | R50: =IFERROR(tb_investimentos[[#This Row],[QUANTIDADE]]*tb_investimentos[[#This Row],[PREÇO MERCADO]],"") | S50: =IFERROR(tb_investimentos[[#This Row],[VALOR TOTAL MERCADO]]-tb_investimentos[[#This Row],[VALOR TOTAL PONDERADO]],"") | T50: =IFERROR(_xlfn.XLOOKUP(tb_investimentos[[#This Row],[DESCRIÇÃO]],'INFO AÇÕES'!E:E,'INFO AÇÕES'!H:H),"") | U50: =IFERROR((tb_investimentos[[#This Row],[VALOR TOTAL MERCADO]]-tb_investimentos[[#This Row],[VALOR TOTAL PONDERADO]])/tb_investimentos[[#This Row],[VALOR TOTAL PONDERADO]],"")
B51: Saídas | C51: 46364 | D51: Sabesp | E51: =IF(tb_investimentos[[#This Row],[TIPO MOVIMENTAÇÃO]]="Aporte",_xlfn.XLOOKUP(tb_investimentos[[#This Row],[DESCRIÇÃO]],'INFO AÇÕES'!E:E,'INFO AÇÕES'!I:I),"BRL") -> BRL | F51: Agua | G51: 1 | H51: 25 | I51: Banco do Brasil | J51: =H51*G51 -> 25 | K51: NÃO | L51: =MONTH(tb_investimentos[[#This Row],[DATA]]) -> 12 | M51: =YEAR(tb_investimentos[[#This Row],[DATA]]) -> 2026 | N51: =DAY(tb_investimentos[[#This Row],[DATA]]) -> 8 | O51: =SUMIF($D$5:$D$10000, D51, $J$5:$J$10000) / SUMIF($D$5:$D$10000, D51, $G$5:$G$10000) -> 25 | P51: =tb_investimentos[[#This Row],[PREÇO MÉDIO PONDERADO]]*tb_investimentos[[#This Row],[QUANTIDADE]] -> 25 | Q51: =IFERROR(_xlfn.XLOOKUP(tb_investimentos[[#This Row],[DESCRIÇÃO]],tb_acoes[Símbolo do ticker],tb_acoes[Preço]),"") | R51: =IFERROR(tb_investimentos[[#This Row],[QUANTIDADE]]*tb_investimentos[[#This Row],[PREÇO MERCADO]],"") | S51: =IFERROR(tb_investimentos[[#This Row],[VALOR TOTAL MERCADO]]-tb_investimentos[[#This Row],[VALOR TOTAL PONDERADO]],"") | T51: =IFERROR(_xlfn.XLOOKUP(tb_investimentos[[#This Row],[DESCRIÇÃO]],'INFO AÇÕES'!E:E,'INFO AÇÕES'!H:H),"") | U51: =IFERROR((tb_investimentos[[#This Row],[VALOR TOTAL MERCADO]]-tb_investimentos[[#This Row],[VALOR TOTAL PONDERADO]])/tb_investimentos[[#This Row],[VALOR TOTAL PONDERADO]],"")
